2019-09-13 13:38:56 WARNING [11990-Thread-1] log.log_response line 228: Not Found: /execl
2019-09-13 13:38:56 WARNING [11990-Thread-1] basehttp.log_message line 154: "GET /execl HTTP/1.1" 404 12567
2019-09-13 13:46:38 WARNING [12607-Thread-1] log.log_response line 228: Not Found: /execl
2019-09-13 13:46:38 WARNING [12607-Thread-1] basehttp.log_message line 154: "GET /execl HTTP/1.1" 404 12567
2019-09-13 13:46:41 WARNING [12607-Thread-3] log.log_response line 228: Not Found: /execl
2019-09-13 13:46:41 WARNING [12607-Thread-3] basehttp.log_message line 154: "GET /execl HTTP/1.1" 404 12567
2019-09-13 15:00:38 ERROR [17975-Thread-1] log.log_response line 228: Internal Server Error: /
Traceback (most recent call last):
  File "/home/brother/Documents/oa/venv/lib/python3.5/site-packages/django/core/handlers/exception.py", line 34, in inner
    response = get_response(request)
  File "/home/brother/Documents/oa/venv/lib/python3.5/site-packages/django/core/handlers/base.py", line 115, in _get_response
    response = self.process_exception_by_middleware(e, request)
  File "/home/brother/Documents/oa/venv/lib/python3.5/site-packages/django/core/handlers/base.py", line 113, in _get_response
    response = wrapped_callback(request, *callback_args, **callback_kwargs)
  File "/home/brother/Documents/oa/vote/views.py", line 34, in show_subjects
    subjects.append(SubjectMapper(subjects).as_dict())
AttributeError: 'Subject' object has no attribute 'append'
2019-09-13 15:00:39 ERROR [17975-Thread-1] basehttp.log_message line 154: "GET / HTTP/1.1" 500 84419
2019-09-13 15:10:49 ERROR [18729-Thread-1] log.log_response line 228: Internal Server Error: /
Traceback (most recent call last):
  File "/home/brother/Documents/oa/venv/lib/python3.5/site-packages/django/core/handlers/exception.py", line 34, in inner
    response = get_response(request)
  File "/home/brother/Documents/oa/venv/lib/python3.5/site-packages/django/core/handlers/base.py", line 115, in _get_response
    response = self.process_exception_by_middleware(e, request)
  File "/home/brother/Documents/oa/venv/lib/python3.5/site-packages/django/core/handlers/base.py", line 113, in _get_response
    response = wrapped_callback(request, *callback_args, **callback_kwargs)
  File "/home/brother/Documents/oa/vote/views.py", line 38, in show_subjects
    return JsonResponse(subjects, safe=False)
  File "/home/brother/Documents/oa/venv/lib/python3.5/site-packages/django/http/response.py", line 558, in __init__
    data = json.dumps(data, cls=encoder, json_dumps_params={'ensure_ascii':False})
  File "/usr/lib/python3.5/json/__init__.py", line 237, in dumps
    **kw).encode(obj)
TypeError: __init__() got an unexpected keyword argument 'json_dumps_params'
2019-09-13 15:10:49 ERROR [18729-Thread-1] basehttp.log_message line 154: "GET / HTTP/1.1" 500 95592
